Workbook

Sheet Title
D9: Information Technology Service Agreement System Interface Specification (FIX) for Market Data Distribution System
H17: 2019

Sheet History
A2: Release/Revision history
A4: No | B4: Version | C4: Date | D4: Release/Revision Description | E4: Author
A5: 1 | B5: 0.9 | C5: 2017.06.02 | D5: Initial Writing | E5: Dongeun Kim
A6: 2 | B6: 0.91 | C6: 2017.06.05 | D6: Revision of New Messages being Defined for Vietnam BR | E6: Dongeun Kim
A7: 3 | B7: 0.92 | C7: 2017.07.19 | D7: Revision of Message Structures | E7: Dongeun Kim
A8: 4 | B8: 0.97 | C8: 2017.10.20 | D8: Definition of Tags as Requirements and Revision of Messages | E8: Dongeun Kim
A9: 5 | B9: 0.99 | C9: 2017.11.01 | D9: Add the purposes in Inteface List tab Modify the names of messages referring to the names of usecases | E9: Dongeun Kim
A10: 6 | B10: 0.992 | C10: 2017.11.17 | D10: Split the 'Comment' column to 'Field Meaning' and 'Possible Value' Fill and modify the meaning/possible value of all the words in Tag(Glossary) | E10: Dongeun Kim
A11: 7 | B11: 0.993 | C11: 2017.11.23 | D11: Check the message to MSS in the interface list. | E11: Dongeun Kim
A12: 8 | B12: 0.994 | C12: 2017.12.06 | D12: Update the purposes into detail in Interface List tab Update 'Required' fileds in each interface definition tab | E12: Dongeun Kim
A13: 9 | B13: 0.995 | C13: 2017.12.15 | D13: 1. Modify the definition of tag NoMDEntries(268) and MarketMakerContractCode(30574) 2. Add a new message 'Random End' and add 'Random End Triggering Condition Code' in the definition of Security Definition with related tags 3. Delete 'UnderlyingSecurityID' in the definition of Security Definition, and delete 'BoardEvtID' and 'BoardEvtStartTime' in the definition of Security Status 4. Add 'English Symbol' and 'VWAP' to Tag(Glossary) and Security Definition 5. Update values of user-defined tags from 8000/10000 to 20000/30000 6. Update the Online/Batch type value of Index and Disclosure in Interface List 7. Synchronize the definition of tags with the specification document from trading channel | E13: Dongeun Kim
A14: 10 | B14: 0.996 | C14: 2018.01.12 | D14: 1. Update the entire Field Meanings of the sheet Tag(Glossary) based on other output documents 2. Add SymbolCloseInfoPxType(20027) to the definition of Security Definition 3. Modify the Field Meaning and length of TotalPage(30606) and CurrentPage(30607), and add those fields to 'Index Constituents Information' message | E14: Dongeun Kim
A15: 11 | B15: 0.997 | C15: 2018.01.19 | D15: 1. Modify the field name and meaning ClassID(20009) to ProductID(20009) 2. Delete the tag SecurityGroup(1151) and modify the tags in definition to ProductID(20009) 3. Delete checks of the messages to MSS in interface list 4. Move the message 'RandomEnd(MW)' to trans type of market data in interface list 5. Delete the message 'Dynamic Price Limit(MG)' which is not included in VN 6. Delete the message 'Issuer Information(MJ)' and 'Member(Dealer) Information(MK)' as change of business requirement 7. Add the message 'Price Limit Expansion(MX)' and 'Quantity Allocation(MY)' in interface list 8. Modify field meaning and length of DisparateRatio(30602) to merge with DisparateSign(30601), and delete DisparateSign(30601) 9. Modify the name and fields of the message 'Reference Price Determination(M7)' to 'Security Information Notification(M7)' 10. Add ListedShares(20020) to the definition of Security Definition 11. Modify field meaning and possible value of all the tags to synchronize their definition of the document VN_CHN_DS_System Interface Specification(FIX) | E15: Dongeun Kim
A16: 12 | B16: 0.9971 | C16: 2018.02.09 | D16: 1. Modify the field meaning of ForeignerOrderLimitQty(30558) in Tag(Glossary) 2. Remove the possible values of Tag(Glossary) that are not used in VN system. 3. Remove ForeignerLimitRatio(30598) from the message 'Foreigner Order Limit(MF)' 4. Modify the tag name of 30606, 30607 for more general meaning. 5. Delete the message Open Interest(type=MA) due to the modification of business in VSD. | E16: Dongeun Kim
A17: 13 | B17: 0.9974 | C17: 2018.02.20 | D17: 1. Add the tag SecurityID(48); change all the definition using Symbol(55) to SecurityID(48). 2. Remove the tag EnglishSymbol(30624); change the tag EnglishSymbol(30624) in the definition of 'Security Definition' to Symbol(55), and modify the definition of Symbol(55) 3. Delete the field HaltReason(327) from the definition of Security Status 4. Modify the possible value of the tag SecurityStatus(965) and ForeignInvestorTypeCode(30581) 5. Add a new tag TscProductGroupID(30628) to be substituted the tag SecurityType(167) 6. Modify the field meaning of the tag ForeignerOrderLimitQty(30558) 7. Modify the field meaning of the tag Yield(236) in Tag(Glossary) 8. Add a new tag DynamicVIBasePrice(20047) and DynamicVIDispartiyRatio(20048) in 'Volatility Interruption' 9. Delete the tag MarketMakerContractCode(30574) in 'Market Maker Information' 10. Add the tag SecurityID(48) and SecurityIDSource(22) in 'Market Maker Information' 11. Modify the field meaning of the tag TotalMsgNo(30606) and CurrentMsgNo(30607) 12. Modify the field meaning of the tag SellTotOrderQty(30521), BuyTotOrderQty(30522), SellValidOrderCnt(30523), BuyValidOrderCnt(30524) 13. Change wording in every field meaning: issue → security 14. Update definition of ‘number” format length 15. Delete 'Security Board(M6)' message; its purpose (to list securities) is covered by 'Security Definition(d)' | E17: Dongeun Kim
A18: 14 | B18: 0.998 | C18: 2018.02.27 | D18: 1. Merge the definition of the messages Price + Price(Bond), Deem Trade Price + Deem Trade Price(Bond) 2. Rollback the modification 1. and 2. in the version 0.9973; SecurityID(48) => Symbol(55), Symbol(55) => EnglishSymbol(30624) 3. Delete SecurityIDSource(22) in the Tag(Glossary) and all the definitions | E18: Dongeun Kim
A19: 15 | B19: 0.9981 | C19: 2018.03.02 | D19: 1. Change the field name of EnglishSymbol(30624) to TickerCode(30624) 2. Add new tags SymbolShortCode(30628), SymbolName(30629), SymbolEnglishName(30630) 3. Add SymbolShortCode(30628), SymbolName(30629), SymbolEnglishName(30630) and remove SecurityDesc(107) in the definition of 'SecurityDefinition' 4. Modify the field meaning of Symbol(55) | E19: Dongeun Kim
A20: 16 | B20: 0.9982 | C20: 2018.03.09 | D20: 1. Modify the possible value of TransactTime(60) from YYYYMMDD HH:MM:SS.sss to HHmmSSsss 2. Modify the length of PriceFluctuationRatio(30603) from 9 to 10 3. Delete repeating groups in the definition of 'Trading Result of Foreign Investors(MT)', and delete the tag FornInvestTypeCode(20054); the output is sum of trading results for foreign investors 4. Modify the SecurityDesc(107) to SymbolName(30629) in the definition of 'Disclosure(MU)' 5. Modify the length of ContractMultiplier(231) from 20 to 22(12.8) 6. Modify the length of CouponRate(223) from 14(9.4) to 14(7.5) 7. Modify the length of tags related to trading price from 14(9.4) to 15(9.4) 8. Modify the length of TotalMsgNo(30606) and CurrentMsgNo(30607) from 11 to 15 9. Add SecurityGroupID(30604) in the definition of 'Security Definition(d)' 10. Add new tag ContractSize(30631) to modify the item UnitOfMeasureQty(1147) in 'Security Definition(d)' 11. Delete the tags not used in MDDS 12. Modify the format of all the tags whose formats are 'Number' to 'Price', 'Int' or 'Float' 13. Delete the message 'Quantity Allocation(MY)'; it is not the information distributed by MDDS, which means it is not essencial to receive market data 14. Modify the history of omitted content History No.13 | E20: Dongeun Kim
A21: 17 | B21: 0.9983 | C21: 2018.03.19 | D21: 1. Modify the definitions of tags to synchronize the output of other parts 2. Delete the tags not used in MDDS 3. Add new tags IdxName(30632) and IdxEnglishName(30633), and add the tags to 'Index Constituents Information(ML)' in the definition 4. Rollback the deletion of tag OpenInterestQty(30540) for error correction 5. Modify the length of TransactTime(60) from 21 to 9; MDDS uses this field without date information 6. Modify the tag Symbol(55) to MarketMakerContractUnit(30574) in the definition of message 'Market Maker Information(MH)'; Rollback the modification 9. and 10. in the version 0.9974 7. Modify the possible values of MsgType(35) in the sheet 'Header' 8. Delete BordID(20054) in the definition of 'Investor per Industry(M2)', 'Investor per Symbol(M3)', 'Top N Members per Symbol(M4)', 'Top N Symbols(MP, MQ, MR, MS)'; those statistics merges not per {Symbol, Board} but per {Symbol}. 9. Rollback the deletion of the message 'Open Interest(MA)' as EOD distribution 10. Rollback the deletion of repeating groups in the definition of 'Trading Result of Foreign Investors(MT)' which is history No.3 in the version 0.9982 | E21: Dongeun Kim
... A46: 41 | B46: 0.9A16 | C46: 2023.09.05 | D46: 1. Delete TransactTime(60) from the definition of 'Open Interest(MA)' 2. Modify Req'd field of SellTotOrderQty, BuyTotOrderQty, SellValidOrderCnt, BuyValidOrderCnt, NumberOfOrders in 'Price Recovery(W)' 3. Modify the description of possible values for MDEntryType(269) 4. Add the message '(Block Trade) Price Recovery (W)' and '(Block Trade) Price Recovery (Bond) (W)' in interface list | E46: Hyungshik Ju

Sheet Guildline
B2: Guideline
B4: No. | C4: Sort | D4: Item | E4: Guideline
B5: 1 | C5: Interface List | D5: TransType | E5: Write the Sending Message Type.
B6: 2 | C6: Interface List | D6: Interface ID | E6: Assign ID to verify the interface. - Rules for assigning Interface ID : VN_Business Code(3 Digits) of Sending System_IF_Message Format_Serial Number - Message Format : FIX, FL(Fixed Length) etc. Ex) If sender is Trading system : VN_TRS_IF_FIX_0001
B7: 3 | C7: Interface List | D7: Interface Name | E7: Write the FIX Message title. Go to the Interface Definition when clicking title.
B8: 4 | C8: Interface List | D8: MsgType | E8: Write the type of the message.
B9: 5 | C9: Interface List | D9: Realtime/Batch | E9: R: Realtime B: Batch
B10: 6 | C10: Interface List | D10: Timing | E10: Timing code of message communication - DO: Day Opening (Before or At Market Opening) - ONO: Online (From Day Opening until Market Closing) - ONT: Online (Trading Hours) - ONB: Online (From Market Opening until Daily Batch) - ALL: All Day - MC: Market Closing - DB: Daily Batch - DC: Day Closing (EOD, End of Day)
B11: 7 | C11: Interface List | D11: Transmission Protocol | E11: Write Sending Protocols. - TCP/IP, UDP, etc.
B12: 8 | C12: Interface List | D12: Interface System - FROM | E12: Post '○' on the 'From' system of the Interface.
B13: 9 | C13: Interface List | D13: Interface System - TO | E13: Post '■' on the 'Final Destination(To)' system of the Interface. ※ If Passing Through System is available, then post '□'.
B14: 10 | C14: Interface List | D14: Purpose | E14: Write Remarks and purpose of the message
C16: Inferface Definition | E16: Write Interface Definition Sheet after the Interface List Sheet with the following steps as below. - Tag : Write information of entire Tag that have been used in Interface Definition. - Header : (Common Information) Write Header information of the message. - Add sheet per Interface Receiving System.
B17: 1 | C17: Inferface Definition | D17: Interface ID | E17: Same with the guideline for the interface list above.
B18: 2 | C18: Inferface Definition | D18: Interface Name | E18: Same with the guideline for the interface list above.
B19: 3 | C19: Inferface Definition | D19: Tag | E19: Write Tag number.
B20: 4 | C20: Inferface Definition | D20: Field Name | E20: Write the Field Name.
B21: 5 | C21: Inferface Definition | D21: Req'd | E21: Post 'Y', if it is the required field.
B22: 6 | C22: Inferface Definition | D22: Format | E22: Write the data format of the field.
B23: 7 | C23: Inferface Definition | D23: Length | E23: Write the length of the field.
B24: 8 | C24: Inferface Definition | D24: Comments | E24: Write the definition including the purpose of the field.

Sheet Interface List
B2: Interface List - MDS
B4: No | C4: TransType | D4: Interface ID | E4: Interface Name | F4: MsgType | G4: Realtime /Batch | H4: Timing | I4: Transmission Protocol | J4: Interface System | AJ4: Purpose | AK4: Remark
J5: From | W5: TO
J6: CHN | K6: BND | L6: ME | M6: TRS | N6: M I S | O6: MDS | P6: I N X | Q6: R D S | R6: C S S | S6: DRS | T6: M S S | U6: MEM | V6: BANK | W6: CHN | X6: BND | Y6: ME | Z6: TRS | AA6: M I S | AB6: MDS | AC6: I N X | AD6: R D S | AE6: C S S | AF6: DRS | AG6: M S S | AH6: MEM | AI6: BANK
B7: 1 | C7: Tag | D7: - | E7: FIX Tag | H7: -
B8: 2 | C8: Header | D8: - | E8: FIX Header | H8: -
B9: 3 | C9: Trailer | D9: - | E9: FIX Trailer | H9: -
B10: 4 | C10: ReferenceData | D10: IFMDFIX0001 | E10: Security Definition | F10: d | G10: B | H10: DO | I10: UDP | O10: ○ | AH10: ■ | AJ10: Distribute reference data to receive market data for a security
B11: 5 | D11: IFMDFIX0002 | E11: Security Status | F11: f | G11: R | H11: ONT | I11: UDP | O11: ○ | AH11: ■ | AJ11: Distribute market control to change the status of a security
B12: 7 | D12: IFMDFIX0003 | E12: Security Information Notification | F12: M7 | G12: R | H12: ONT | I12: UDP | O12: ○ | AH12: ■ | AJ12: Distribute determination/notification of reference price, valuation price, or list of shares among market control
B13: 8 | D13: IFMDFIX0004 | E13: Symbol Closing Information | F13: M8 | G13: B | H13: MC | I13: UDP | O13: ○ | AH13: ■ | AJ13: Distribute symbol closing information among market control
B14: 9 | D14: IFMDFIX0005 | E14: Volatility Interruption | F14: MD | G14: R | H14: ONT | I14: UDP | O14: ○ | AH14: ■ | AJ14: Distribute volatility interruption message among market control
B15: 10 | D15: IFMDFIX0006 | E15: Market Maker Information | F15: MH | G15: B | H15: DO | I15: UDP | O15: ○ | AH15: ■ | AJ15: Distribute market maker information where the unit of contracts is symbol for stock/bond market and is product for derivatives
B16: 11 | D16: IFMDFIX0007 | E16: Symbol Event | F16: MI | G16: B | H16: DO | I16: UDP | O16: ○ | AH16: ■ | AJ16: Distribute symbol event for each symbol and the reason of the event for Stock market
B17: 14 | D17: IFMDFIX0008 | E17: Index Constituents Information | F17: ML | G17: B | H17: DO | I17: UDP | O17: ○ | AH17: ■ | AJ17: Distribute the list of constituent securities for each index
B18: 17 | C18: MarketData | D18: IFMDFIX0009 | E18: Price | F18: X | G18: R | H18: ONT | I18: UDP | O18: ○ | AH18: ■ | AJ18: Distribute the repeated structures of best orders in levels for best order messages, and distribute repeated structures of the execution/opening/highest/lowest price for trade messages
B19: 18 | D19: IFMDFIX0010 | E19: Price Recovery | F19: W | G19: R | H19: ONT | I19: UDP | O19: ○ | AH19: ■ | AJ19: Distribute price recovery periodically (automatically)
B20: 19 | D20: IFMDFIX0011 | E20: Price Recovery(Bond) | F20: W | G20: R | H20: ONT | I20: UDP | O20: ○ | AH20: ■ | AJ20: Distribute price recovery with yield periodically (automatically)
B21: 20 | D21: IFMDFIX0012 | E21: (Block Trade) Price Recovery | F21: W | G21: R | H21: ONT | I21: UDP | O21: ○ | AH21: ■ | AJ21: Distribute price recovery periodically (automatically)
B22: 21 | D22: IFMDFIX0013 | E22: (Block Trade) Price Recovery(Bond) | F22: W | G22: R | H22: ONT | I22: UDP | O22: ○ | AH22: ■ | AJ22: Distribute price recovery with yield periodically (automatically)
B23: 22 | D23: IFMDFIX0014 | E23: Index | F23: M1 | G23: R | H23: ONT | I23: UDP | O23: ○ | AH23: ■ | AJ23: Distribute index periodically during trading time and EOD(from the end of the maket to termination of process) The indices which are calculated only in EOD are distributed by batch process
B24: 23 | D24: IFMDFIX0015 | E24: Investor per Industry | F24: M2 | G24: R | H24: ONT | I24: UDP | O24: ○ | AH24: ■ | AJ24: Distribute sum of trade by investor in the structures repeated for each industry
B25: 24 | D25: IFMDFIX0016 | E25: Investor per Industry(Bond) | F25: M2 | G25: R | H25: ONT | I25: UDP | O25: ○ | AH25: ■ | AJ25: Distribute sum of trade by investor in the structures repeated for each bond cartegory
B26: 25 | D26: IFMDFIX0017 | E26: Investor per Industry(Derivatives) | F26: M2 | G26: R | H26: ONT | I26: UDP | O26: ○ | AH26: ■ | AJ26: Distribute sum of trade by investor in the structures repeated for each future/option market
B27: 26 | D27: IFMDFIX0018 | E27: Investor per Symbol | F27: M3 | G27: B | H27: MC | I27: UDP | O27: ○ | AH27: ■ | AJ27: Distribute sum of trade by investor in the structures repeated for each symbol
B28: 27 | D28: IFMDFIX0019 | E28: Top N Members per Symbol | F28: M4 | G28: R | H28: ONB | I28: UDP | O28: ○ | AH28: ■ | AJ28: Distribute top N members in the structures repeated for each symbol
B29: 28 | D29: IFMDFIX0020 | E29: Open Interest | F29: MA | G29: B | H29: DB | I29: UDP | O29: ○ | AH29: ■ | AJ29: Distribute open interest received from VSD in EOD
B30: 29 | D30: IFMDFIX0021 | E30: Deem Trade Price | F30: ME | G30: R | H30: ONT | I30: UDP | O30: ○ | AH30: ■ | AJ30: Distribute deem trade price with yield for pre-opening session
... B43: 42 | D43: IFMDFIX0034 | E43: Time Stamp (Polling) | F43: MV | G43: R | H43: ALL | I43: UDP | O43: ○ | AH43: ■ | AJ43: Distribute time stamp to check polling for each physical network line

Sheet Tag(Glossary)
B2: Tag
B4: Tag | C4: Field Name | D4: Req'd | E4: Format | F4: Length | G4: Field Meaning | H4: Possible Value
B5: 8 | C5: BeginString | E5: String | F5: 7 | G5: FIX.4.4
B6: 9 | C6: BodyLength | E6: Int | F6: 6 | G6: Length filed
B7: 10 | C7: CheckSum | E7: String | F7: 3 | G7: Three byte, simple checksum
B8: 15 | C8: Currency | E8: String | F8: 3 | G8: Currency code on ISO 4217 | H8: VND: Vietnamese Dong USD: US Dollar EUR: Euro
B9: 34 | C9: MsgSeqNum | E9: Int | F9: 11 | G9: Session sequence number
B10: 35 | C10: MsgType | E10: String | F10: 3 | G10: Refer to 'Header' sheet of the document 'VN_MDS_DS_SystemInterfaceSpecification(FIX)'
B11: 49 | C11: SenderCompID | E11: String | F11: 16 | G11: Sender(Member CompID)
B12: 52 | C12: SendingTime | E12: UTCTime | F12: 21 | G12: Time of message transmission | H12: YYYYMMDD HH:MM:SS.sss
B13: 55 | C13: Symbol | E13: String | F13: 12 | G13: The unique code of an issue (a.k.a. instrument or symbol). Generally it is ISIN code but in case of Repo market it is defined as the exchange staffs want
B14: 56 | C14: TargetCompID | E14: String | F14: 16 | G14: Target(Counter Member CompID) | H14: * Member side, VOTGW = HOSE FIX gateway VXTGW = HNX FIX gateway
B15: 60 | C15: TransactTime | E15: UTCTime | F15: 9 | G15: Time of execution/order creation | H15: HHmmSSsss : Normal Case
B16: 75 | C16: TradeDate | E16: LocalMktDate | F16: 8 | G16: Indicates local date of trade refereneced in this message in YYYYMMDD format. | H16: YYYYMMDD
B17: 83 | C17: RptSeq | E17: Int | F17: 9 | G17: Data sequential number within repeated record
B18: 106 | C18: Issuer | E18: String | F18: 10 | G18: Issuer's unique ID
B19: 140 | C19: PrevClosePx | E19: Price | F19: 15(9.4) | G19: Prev Close Price
B20: 148 | C20: Headline | E20: String | F20: 250 | G20: TEXT Format
B21: 200 | C21: MaturityMonthYear | E21: String | F21: 6 | G21: Expiration or maturity month (YYYYMM)
B22: 201 | C22: PutOrCall | E22: String | F22: 1 | G22: Rights type code of derivatives | H22: P = Put C = Call
B23: 202 | C23: StrikePrice | E23: Price | F23: 18(9.8) | G23: Exercise (strike) price of options or Subscription Warrant
B24: 207 | C24: SecurityExchange | E24: String | F24: 2 | G24: The unique ID assigned by Exchange | H24: HO: HoSE HX: HNX
B25: 223 | C25: CouponRate | E25: Float | F25: 14(7.5) | G25: Rate of return of a bond. Coupon Rate = Annual Interest Payments / Par Value
B26: 225 | C26: IssueDate | E26: String | F26: 8 | G26: Issued date | H26: YYYYMMDD
B27: 231 | C27: ContractMultiplier | E27: Float | F27: 22(12.8) | G27: Trading multiplier for calculating trading or settlement amount
B28: 236 | C28: Yield | E28: Float | F28: 13(5.6) | G28: Yield to maturity based on Reference Price
B29: 268 | C29: NoMDEntries | E29: Int | F29: 9 | G29: Number(Depth) of market data entries repeated as following
B30: 269 | C30: MDEntryType | E30: String | F30: 1 | G30: Data classification for an entry of market data | H30: Possible values in message X (Price) . 0 = Bid 1 = Offer 2 = Trade 4 = Opening Price 7 = Trading Session High Price 8 = Trading Session Low Price Possible values in message W (Price Recovery) . 0 = Bid 1 = Offer
B31: 270 | C31: MDEntryPx | E31: Price | F31: 15(9.4) | G31: Price for an entry of market data
B32: 271 | C32: MDEntrySize | E32: Int | F32: 12 | G32: Size (or quantity) for an entry of market data
B33: 279 | C33: MDUpdateAction | E33: String | F33: 1 | G33: Type code of update action for an entry of market data | H33: 0 = New
B34: 290 | C34: MDEntryPositionNo | E34: Int | F34: 2 | G34: Position no (or level) for an entry of market data
B35: 330 | C35: BuyVolume | E35: Int | F35: 12 | G35: Trading volume in buy side
B36: 331 | C36: SellVolume | E36: Int | F36: 12 | G36: Trading volume in sell side
B37: 336 | C37: TradingSessionID | E37: String | F37: 2 | G37: Trading Session | H37: 01 = GT Order Load 10 = Opening Call Auction 11 = Opening Call Auction Extension 20 = Call Auction after Halt 21 = Call Auction after Halt Extension 30 = Closing Call Auction 40 = Continuous Auction 50 = VI Call Auction 51 = VI Call Auction Extension 60 = Order Accept Only 80 = Periodic Call Auction 90 = Trading Halt 99 = Board Closing
B38: 346 | C38: NumberOfOrders | E38: Int | F38: 11 | G38: Number of orders
B39: 381 | C39: GrossTradeAmt | E39: Float | F39: 23(18.4) | G39: Gross amount traded
B40: 387 | C40: TotalVolumeTraded | E40: Int | F40: 12 | G40: Total volume traded
B41: 541 | C41: MaturityDate | E41: String | F41: 8 | G41: Expiration or maturity date | H41: YYYYMMDD
B42: 911 | C42: TotNumReports | E42: Int | F42: 16 | G42: Entire number of messages for issue information transmission or for a set of statistics results
...

Sheet Header
B2: Header
B4: Tag | C4: Field Name | D4: Req'd | E4: Format | F4: Length | G4: Comments
B5: 8 | C5: =VLOOKUP($B5,'Tag(Glossary)'!$B:$G,2,0) -> BeginString | D5: Y | E5: =VLOOKUP($B5,'Tag(Glossary)'!$B:$G,4,0) -> String | F5: =VLOOKUP($B5,'Tag(Glossary)'!$B:$G,5,0) -> 7 | G5: =VLOOKUP($B5,'Tag(Glossary)'!$B:$G,6,0) -> FIX.4.4
B6: 9 | C6: =VLOOKUP($B6,'Tag(Glossary)'!$B:$G,2,0) -> BodyLength | D6: Y | E6: =VLOOKUP($B6,'Tag(Glossary)'!$B:$G,4,0) -> Int | F6: =VLOOKUP($B6,'Tag(Glossary)'!$B:$G,5,0) -> 6 | G6: =VLOOKUP($B6,'Tag(Glossary)'!$B:$G,6,0) -> Length filed
B7: 35 | C7: =VLOOKUP($B7,'Tag(Glossary)'!$B:$G,2,0) -> MsgType | D7: Y | E7: =VLOOKUP($B7,'Tag(Glossary)'!$B:$G,4,0) -> String | F7: =VLOOKUP($B7,'Tag(Glossary)'!$B:$G,5,0) -> 3 | G7: =VLOOKUP($B7,'Tag(Glossary)'!$B:$G,6,0) -> Refer to 'Header' sheet of the document 'VN_MDS_DS_SystemInterfaceSpecification(FIX)'
B8: 49 | C8: =VLOOKUP($B8,'Tag(Glossary)'!$B:$G,2,0) -> SenderCompID | D8: Y | E8: =VLOOKUP($B8,'Tag(Glossary)'!$B:$G,4,0) -> String | F8: =VLOOKUP($B8,'Tag(Glossary)'!$B:$G,5,0) -> 16 | G8: =VLOOKUP($B8,'Tag(Glossary)'!$B:$G,6,0) -> Sender(Member CompID)
B9: 56 | C9: =VLOOKUP($B9,'Tag(Glossary)'!$B:$G,2,0) -> TargetCompID | D9: Y | E9: =VLOOKUP($B9,'Tag(Glossary)'!$B:$G,4,0) -> String | F9: =VLOOKUP($B9,'Tag(Glossary)'!$B:$G,5,0) -> 16 | G9: =VLOOKUP($B9,'Tag(Glossary)'!$B:$G,6,0) -> Target(Counter Member CompID)
B10: 34 | C10: =VLOOKUP($B10,'Tag(Glossary)'!$B:$G,2,0) -> MsgSeqNum | D10: Y | E10: =VLOOKUP($B10,'Tag(Glossary)'!$B:$G,4,0) -> Int | F10: =VLOOKUP($B10,'Tag(Glossary)'!$B:$G,5,0) -> 11 | G10: =VLOOKUP($B10,'Tag(Glossary)'!$B:$G,6,0) -> Session sequence number
B11: 52 | C11: =VLOOKUP($B11,'Tag(Glossary)'!$B:$G,2,0) -> SendingTime | D11: Y | E11: =VLOOKUP($B11,'Tag(Glossary)'!$B:$G,4,0) -> UTCTime | F11: =VLOOKUP($B11,'Tag(Glossary)'!$B:$G,5,0) -> 21 | G11: =VLOOKUP($B11,'Tag(Glossary)'!$B:$G,6,0) -> Time of message transmission
B13: * Specification of MsyType(35)
C14: d = Security Definition
C15: f = Secrity Status
C16: X = Price
C17: W = Price Recovery
C18: M1 = Index
C19: M2 = Investor per Industry
C20: M3 = Investor per Symbol
C21: M4 = Top N Members per Symbol
C22: M7 = Security Information Notification
C23: M8 = Symbol Closing Information
C24: MD = Volatility Interruption
C25: MA = Open Interest
... C42: MX = Price Limit Expansion

Sheet Trailer
B2: Trailer
B4: Tag | C4: Field Name | D4: Req'd | E4: Format | F4: Length | G4: Comments
B5: 10 | C5: =VLOOKUP($B5,'Tag(Glossary)'!$B:$G,2,0) -> CheckSum | D5: Y | E5: =VLOOKUP($B5,'Tag(Glossary)'!$B:$G,4,0) -> String | F5: =VLOOKUP($B5,'Tag(Glossary)'!$B:$G,5,0) -> 3 | G5: =VLOOKUP($B5,'Tag(Glossary)'!$B:$G,6,0) -> Three byte, simple checksum

Sheet Security Definition
B2: Security Definition
B4: Interface ID | C4: Interface Name | D4: Tag | E4: Field Name | F4: Req'd | G4: Format | H4: Length | I4: Comments
B5: =INDEX('Interface List'!$D$7:$D$45,MATCH($C5,'Interface List'!$E$7:$E$45,0)) -> IFMDFIX0001 | C5: Security Definition | E5: Standard Header | F5: Y | I5: MsgType = d
B6: =INDEX('Interface List'!$D$7:$D$45,MATCH($C6,'Interface List'!$E$7:$E$45,0)) -> IFMDFIX0001 | C6: Security Definition | D6: 30001 | E6: =VLOOKUP($D6,'Tag(Glossary)'!$B:$G,2,0) -> MarketID | F6: Y | G6: =VLOOKUP($D6,'Tag(Glossary)'!$B:$G,4,0) -> String | H6: =VLOOKUP($D6,'Tag(Glossary)'!$B:$G,5,0) -> 3 | I6: =VLOOKUP($D6,'Tag(Glossary)'!$B:$H,6,0)&IF(ISBLANK(VLOOKUP($D6,'Tag(Glossary)'!$B:$H,7,0)),"",CHAR(10))&VLOOKUP($D6,'Tag(Glossary)'!$B:$H,7,0) -> ID for identifying the market <Hochiminh Exchange> - STO: HoSE Stock Market - BDO: HoSE Bond Market - RPO: HoSE Repo Market <Hanoi Exchange> - STX: HNX Listed Stock Market - BDX: HNX Government Bond Market - DVX: HNX Derivative Market - UPX: HNX UpCoM Stock Market - HCX: HNX Corporate Bond Market
B7: =INDEX('Interface List'!$D$7:$D$45,MATCH($C7,'Interface List'!$E$7:$E$45,0)) -> IFMDFIX0001 | C7: Security Definition | D7: 20004 | E7: =VLOOKUP($D7,'Tag(Glossary)'!$B:$G,2,0) -> BoardID | F7: Y | G7: =VLOOKUP($D7,'Tag(Glossary)'!$B:$G,4,0) -> String | H7: =VLOOKUP($D7,'Tag(Glossary)'!$B:$G,5,0) -> 2 | I7: =VLOOKUP($D7,'Tag(Glossary)'!$B:$H,6,0)&IF(ISBLANK(VLOOKUP($D7,'Tag(Glossary)'!$B:$H,7,0)),"",CHAR(10))&VLOOKUP($D7,'Tag(Glossary)'!$B:$H,7,0) -> Unique identifier to a Board where a given instrument is traded G1 : Main G2 : Pre open G3 : Post closing G4 : Odd lot G7 : Buy-in G8 : Sell-out T1 : Negotiation (regular) T4 : Negotiation (regular for Odd lot) T2 : Negotiation (pre) T3 : Negotiation (post) T6 : Negotiation (post for Odd lot) R1 : Negotiation (Repo) AL : All Boards
B8: =INDEX('Interface List'!$D$7:$D$45,MATCH($C8,'Interface List'!$E$7:$E$45,0)) -> IFMDFIX0001 | C8: Security Definition | D8: 911 | E8: =VLOOKUP($D8,'Tag(Glossary)'!$B:$G,2,0) -> TotNumReports | F8: Y | G8: =VLOOKUP($D8,'Tag(Glossary)'!$B:$G,4,0) -> Int | H8: =VLOOKUP($D8,'Tag(Glossary)'!$B:$G,5,0) -> 16 | I8: =VLOOKUP($D8,'Tag(Glossary)'!$B:$H,6,0)&IF(ISBLANK(VLOOKUP($D8,'Tag(Glossary)'!$B:$H,7,0)),"",CHAR(10))&VLOOKUP($D8,'Tag(Glossary)'!$B:$H,7,0) -> Entire number of messages for issue information transmission or for a set of statistics results
B9: =INDEX('Interface List'!$D$7:$D$45,MATCH($C9,'Interface List'!$E$7:$E$45,0)) -> IFMDFIX0001 | C9: Security Definition | D9: 207 | E9: =VLOOKUP($D9,'Tag(Glossary)'!$B:$G,2,0) -> SecurityExchange | F9: Y | G9: =VLOOKUP($D9,'Tag(Glossary)'!$B:$G,4,0) -> String | H9: =VLOOKUP($D9,'Tag(Glossary)'!$B:$G,5,0) -> 2 | I9: =VLOOKUP($D9,'Tag(Glossary)'!$B:$H,6,0)&IF(ISBLANK(VLOOKUP($D9,'Tag(Glossary)'!$B:$H,7,0)),"",CHAR(10))&VLOOKUP($D9,'Tag(Glossary)'!$B:$H,7,0) -> The unique ID assigned by Exchange HO: HoSE HX: HNX
B10: =INDEX('Interface List'!$D$7:$D$45,MATCH($C10,'Interface List'!$E$7:$E$45,0)) -> IFMDFIX0001 | C10: Security Definition | D10: 55 | E10: =VLOOKUP($D10,'Tag(Glossary)'!$B:$G,2,0) -> Symbol | F10: Y | G10: =VLOOKUP($D10,'Tag(Glossary)'!$B:$G,4,0) -> String | H10: =VLOOKUP($D10,'Tag(Glossary)'!$B:$G,5,0) -> 12 | I10: =VLOOKUP($D10,'Tag(Glossary)'!$B:$H,6,0)&IF(ISBLANK(VLOOKUP($D10,'Tag(Glossary)'!$B:$H,7,0)),"",CHAR(10))&VLOOKUP($D10,'Tag(Glossary)'!$B:$H,7,0) -> The unique code of an issue (a.k.a. instrument or symbol). Generally it is ISIN code but in case of Repo market it is defined as the exchange staffs want
B11: =INDEX('Interface List'!$D$7:$D$45,MATCH($C11,'Interface List'!$E$7:$E$45,0)) -> IFMDFIX0001 | C11: Security Definition | D11: 30624 | E11: =VLOOKUP($D11,'Tag(Glossary)'!$B:$G,2,0) -> TickerCode | F11: Y | G11: =VLOOKUP($D11,'Tag(Glossary)'!$B:$G,4,0) -> String | H11: =VLOOKUP($D11,'Tag(Glossary)'!$B:$G,5,0) -> 20 | I11: =VLOOKUP($D11,'Tag(Glossary)'!$B:$H,6,0)&IF(ISBLANK(VLOOKUP($D11,'Tag(Glossary)'!$B:$H,7,0)),"",CHAR(10))&VLOOKUP($D11,'Tag(Glossary)'!$B:$H,7,0) -> Symbolic characters of an instrument. It might be used as ticker code (a.k.a. trading code, local code, stock code, bond code and so forth)
B12: =INDEX('Interface List'!$D$7:$D$45,MATCH($C12,'Interface List'!$E$7:$E$45,0)) -> IFMDFIX0001 | C12: Security Definition | D12: 30628 | E12: =VLOOKUP($D12,'Tag(Glossary)'!$B:$G,2,0) -> SymbolShortCode | F12: Y | G12: =VLOOKUP($D12,'Tag(Glossary)'!$B:$G,4,0) -> String | H12: =VLOOKUP($D12,'Tag(Glossary)'!$B:$G,5,0) -> 9 | I12: =VLOOKUP($D12,'Tag(Glossary)'!$B:$H,6,0)&IF(ISBLANK(VLOOKUP($D12,'Tag(Glossary)'!$B:$H,7,0)),"",CHAR(10))&VLOOKUP($D12,'Tag(Glossary)'!$B:$H,7,0) -> A short unique code for an instrument which is determined at exchange and used for more convenience than 12-digit instrument code (ISIN code). It may be used as a part of Repo instrument's ISIN code
B13: =INDEX('Interface List'!$D$7:$D$45,MATCH($C13,'Interface List'!$E$7:$E$45,0)) -> IFMDFIX0001 | C13: Security Definition | D13: 30629 | E13: =VLOOKUP($D13,'Tag(Glossary)'!$B:$G,2,0) -> SymbolName | F13: Y | G13: =VLOOKUP($D13,'Tag(Glossary)'!$B:$G,4,0) -> String | H13: =VLOOKUP($D13,'Tag(Glossary)'!$B:$G,5,0) -> 120 | I13: =VLOOKUP($D13,'Tag(Glossary)'!$B:$H,6,0)&IF(ISBLANK(VLOOKUP($D13,'Tag(Glossary)'!$B:$H,7,0)),"",CHAR(10))&VLOOKUP($D13,'Tag(Glossary)'!$B:$H,7,0) -> Instrument name
B14: =INDEX('Interface List'!$D$7:$D$45,MATCH($C14,'Interface List'!$E$7:$E$45,0)) -> IFMDFIX0001 | C14: Security Definition | D14: 30630 | E14: =VLOOKUP($D14,'Tag(Glossary)'!$B:$G,2,0) -> SymbolEnglishName | F14: Y | G14: =VLOOKUP($D14,'Tag(Glossary)'!$B:$G,4,0) -> String | H14: =VLOOKUP($D14,'Tag(Glossary)'!$B:$G,5,0) -> 80 | I14: =VLOOKUP($D14,'Tag(Glossary)'!$B:$H,6,0)&IF(ISBLANK(VLOOKUP($D14,'Tag(Glossary)'!$B:$H,7,0)),"",CHAR(10))&VLOOKUP($D14,'Tag(Glossary)'!$B:$H,7,0) -> Instrument English name
B15: =INDEX('Interface List'!$D$7:$D$45,MATCH($C15,'Interface List'!$E$7:$E$45,0)) -> IFMDFIX0001 | C15: Security Definition | D15: 20009 | E15: =VLOOKUP($D15,'Tag(Glossary)'!$B:$G,2,0) -> ProductID | F15: Y | G15: =VLOOKUP($D15,'Tag(Glossary)'!$B:$G,4,0) -> String | H15: =VLOOKUP($D15,'Tag(Glossary)'!$B:$G,5,0) -> 11 | I15: =VLOOKUP($D15,'Tag(Glossary)'!$B:$H,6,0)&IF(ISBLANK(VLOOKUP($D15,'Tag(Glossary)'!$B:$H,7,0)),"",CHAR(10))&VLOOKUP($D15,'Tag(Glossary)'!$B:$H,7,0) -> Product is a layer or unit to define or manage rules of trading, clearing and settlement, instrument creating, calculating statistics, etc. Product ID is assigned to Product ID created by combination of exchange, market, security group, underlying asset and currency List of Products (ID and description) will be defined later.
B16: =INDEX('Interface List'!$D$7:$D$45,MATCH($C16,'Interface List'!$E$7:$E$45,0)) -> IFMDFIX0001 | C16: Security Definition | D16: 20003 | E16: =VLOOKUP($D16,'Tag(Glossary)'!$B:$G,2,0) -> ProductGrpID | F16: Y | G16: =VLOOKUP($D16,'Tag(Glossary)'!$B:$G,4,0) -> String | H16: =VLOOKUP($D16,'Tag(Glossary)'!$B:$G,5,0) -> 3 | I16: =VLOOKUP($D16,'Tag(Glossary)'!$B:$H,6,0)&IF(ISBLANK(VLOOKUP($D16,'Tag(Glossary)'!$B:$H,7,0)),"",CHAR(10))&VLOOKUP($D16,'Tag(Glossary)'!$B:$H,7,0) -> Indicates Product Group ID which is defined in the trading system. Product Group is a group of Products that share the trading schedule. STO : Stock Market Product Group BDO : Bond Market Product Group RPO : Repo Market Prodcut Group STX : Listed Stock Market Product Group UPX : UPCOM Product Group BDX : Government Bond Product Group FIO : Index Future Product Group FBX : Bond Future Product Group HCX : Corporate Bond Product Group
B17: =INDEX('Interface List'!$D$7:$D$45,MATCH($C17,'Interface List'!$E$7:$E$45,0)) -> IFMDFIX0001 | C17: Security Definition | D17: 30604 | E17: =VLOOKUP($D17,'Tag(Glossary)'!$B:$G,2,0) -> SecurityGroupID | F17: Y | G17: =VLOOKUP($D17,'Tag(Glossary)'!$B:$G,4,0) -> String | H17: =VLOOKUP($D17,'Tag(Glossary)'!$B:$G,5,0) -> 2 | I17: =VLOOKUP($D17,'Tag(Glossary)'!$B:$H,6,0)&IF(ISBLANK(VLOOKUP($D17,'Tag(Glossary)'!$B:$H,7,0)),"",CHAR(10))&VLOOKUP($D17,'Tag(Glossary)'!$B:$H,7,0) -> Security group ID (Stock, Investment Trust, Futures, Option, etc.)
... B52: =INDEX('Interface List'!$D$7:$D$45,MATCH($C52,'Interface List'!$E$7:$E$45,0)) -> IFMDFIX0001 | C52: Security Definition | D52: 30652 | E52: =VLOOKUP($D52,'Tag(Glossary)'!$B:$G,2,0) -> RedumptionDate | F52: N | G52: =VLOOKUP($D52,'Tag(Glossary)'!$B:$G,4,0) -> String | H52: =VLOOKUP($D52,'Tag(Glossary)'!$B:$G,5,0) -> 8 | I52: =VLOOKUP($D52,'Tag(Glossary)'!$B:$H,6,0)&IF(ISBLANK(VLOOKUP($D52,'Tag(Glossary)'!$B:$H,7,0)),"",CHAR(10))&VLOOKUP($D52,'Tag(Glossary)'!$B:$H,7,0) -> Redumption date YYYYMMDD
B53: =INDEX('Interface List'!$D$7:$D$45,MATCH($C53,'Interface List'!$E$7:$E$45,0)) -> IFMDFIX0001 | C53: Security Definition | E53: Standard Trailer | F53: Y

Sheet Security Status
B2: Security Status
B4: Interface ID | C4: Interface Name | D4: Tag | E4: Field Name | F4: Req'd | G4: Format | H4: Length | I4: Comments
B5: =INDEX('Interface List'!$D$7:$D$45,MATCH($C5,'Interface List'!$E$7:$E$45,0)) -> IFMDFIX0002 | C5: Security Status | E5: Standard Header | F5: Y | I5: MsgType = f
B6: =INDEX('Interface List'!$D$7:$D$45,MATCH($C6,'Interface List'!$E$7:$E$45,0)) -> IFMDFIX0002 | C6: Security Status | D6: 30001 | E6: =VLOOKUP($D6,'Tag(Glossary)'!$B:$G,2,0) -> MarketID | F6: Y | G6: =VLOOKUP($D6,'Tag(Glossary)'!$B:$G,4,0) -> String | H6: =VLOOKUP($D6,'Tag(Glossary)'!$B:$G,5,0) -> 3 | I6: =VLOOKUP($D6,'Tag(Glossary)'!$B:$H,6,0)&IF(ISBLANK(VLOOKUP($D6,'Tag(Glossary)'!$B:$H,7,0)),"",CHAR(10))&VLOOKUP($D6,'Tag(Glossary)'!$B:$H,7,0) -> ID for identifying the market <Hochiminh Exchange> - STO: HoSE Stock Market - BDO: HoSE Bond Market - RPO: HoSE Repo Market <Hanoi Exchange> - STX: HNX Listed Stock Market - BDX: HNX Government Bond Market - DVX: HNX Derivative Market - UPX: HNX UpCoM Stock Market - HCX: HNX Corporate Bond Market
B7: =INDEX('Interface List'!$D$7:$D$45,MATCH($C7,'Interface List'!$E$7:$E$45,0)) -> IFMDFIX0002 | C7: Security Status | D7: 30648 | E7: =VLOOKUP($D7,'Tag(Glossary)'!$B:$G,2,0) -> TscProdGrpId | F7: Y | G7: =VLOOKUP($D7,'Tag(Glossary)'!$B:$G,4,0) -> String | H7: =VLOOKUP($D7,'Tag(Glossary)'!$B:$G,5,0) -> 3 | I7: =VLOOKUP($D7,'Tag(Glossary)'!$B:$H,6,0)&IF(ISBLANK(VLOOKUP($D7,'Tag(Glossary)'!$B:$H,7,0)),"",CHAR(10))&VLOOKUP($D7,'Tag(Glossary)'!$B:$H,7,0) -> ID for identifying the set of the same TSC(Trading Schedule Control) target products. A logical unit controlled by the same schedule. ▦▦ IDs ▦▦ STO : HoSE Stock BDO : HoSE Bond RPO : HoSE Repo BDX : Government Bond FIO : HoSE Index Futures FBX : HNX Bond Futures STX : HNX Stock UPX : HNX UpCom HCX : HNX Corporate Bond ALL : All TSC Products Group
B8: =INDEX('Interface List'!$D$7:$D$45,MATCH($C8,'Interface List'!$E$7:$E$45,0)) -> IFMDFIX0002 | C8: Security Status | D8: 20004 | E8: =VLOOKUP($D8,'Tag(Glossary)'!$B:$G,2,0) -> BoardID | F8: Y | G8: =VLOOKUP($D8,'Tag(Glossary)'!$B:$G,4,0) -> String | H8: =VLOOKUP($D8,'Tag(Glossary)'!$B:$G,5,0) -> 2 | I8: =VLOOKUP($D8,'Tag(Glossary)'!$B:$H,6,0)&IF(ISBLANK(VLOOKUP($D8,'Tag(Glossary)'!$B:$H,7,0)),"",CHAR(10))&VLOOKUP($D8,'Tag(Glossary)'!$B:$H,7,0) -> Unique identifier to a Board where a given instrument is traded G1 : Main G2 : Pre open G3 : Post closing G4 : Odd lot G7 : Buy-in G8 : Sell-out T1 : Negotiation (regular) T4 : Negotiation (regular for Odd lot) T2 : Negotiation (pre) T3 : Negotiation (post) T6 : Negotiation (post for Odd lot) R1 : Negotiation (Repo) AL : All Boards
B9: =INDEX('Interface List'!$D$7:$D$45,MATCH($C9,'Interface List'!$E$7:$E$45,0)) -> IFMDFIX0002 | C9: Security Status | D9: 20005 | E9: =VLOOKUP($D9,'Tag(Glossary)'!$B:$G,2,0) -> BoardEvtID | F9: Y | G9: =VLOOKUP($D9,'Tag(Glossary)'!$B:$G,4,0) -> String | H9: =VLOOKUP($D9,'Tag(Glossary)'!$B:$G,5,0) -> 3 | I9: =VLOOKUP($D9,'Tag(Glossary)'!$B:$H,6,0)&IF(ISBLANK(VLOOKUP($D9,'Tag(Glossary)'!$B:$H,7,0)),"",CHAR(10))&VLOOKUP($D9,'Tag(Glossary)'!$B:$H,7,0) -> Indicates Board event ID which is defined in the trading system. Trading schedule is essentially a sequence (list) of Board events, and each event is identified by three-character code or ID. AA1: Opening CA Open AB1: Cont.A Open AB2: Board Trading Close AC2: Closing CA Execution AD1: Order Reception Start AD2: CA Excecution AE1: Market Halt Release AE8: Market Halt AF1: CA Open after CB AF6: CB Notice AF7: CB Notice Clear AF8: Suspension by CB AQ3: Interface Connection Cut-off AT6: PLE Notice AW8: Lunch Break AW9: Open after Lunch Break AX1: Board Start BB1: Cont.A Open for Non-PCA Instr. BC1: Closing CA Open BE9: Cont.A Open after Market Halt BF9: Cont.A Open after CB CC1: Closing PCA Open CD1: PCA Open CD3: PCA Execution DB2: Trading Close for LTD Instr. DC2: Closing CA Execution for LTD Instr. EI1: Trading Halt Release by Instr./Product EI8: Instr./Product Halt EI9: Cont.A Open after Instr./Product Halt GT1: GT Order Load
B10: =INDEX('Interface List'!$D$7:$D$45,MATCH($C10,'Interface List'!$E$7:$E$45,0)) -> IFMDFIX0002 | C10: Security Status | D10: 20008 | E10: =VLOOKUP($D10,'Tag(Glossary)'!$B:$G,2,0) -> SessOpenCloseCode | F10: N | G10: =VLOOKUP($D10,'Tag(Glossary)'!$B:$G,4,0) -> String | H10: =VLOOKUP($D10,'Tag(Glossary)'!$B:$G,5,0) -> 2 | I10: =VLOOKUP($D10,'Tag(Glossary)'!$B:$H,6,0)&IF(ISBLANK(VLOOKUP($D10,'Tag(Glossary)'!$B:$H,7,0)),"",CHAR(10))&VLOOKUP($D10,'Tag(Glossary)'!$B:$H,7,0) -> Indicates whether a given Board or Session is started or ended. BS : Board Start BE : Board End SS : Session Start SE : Session End SH : Session Halt SR : Session Restart
B11: =INDEX('Interface List'!$D$7:$D$45,MATCH($C11,'Interface List'!$E$7:$E$45,0)) -> IFMDFIX0002 | C11: Security Status | D11: 55 | E11: =VLOOKUP($D11,'Tag(Glossary)'!$B:$G,2,0) -> Symbol | F11: N | G11: =VLOOKUP($D11,'Tag(Glossary)'!$B:$G,4,0) -> String | H11: =VLOOKUP($D11,'Tag(Glossary)'!$B:$G,5,0) -> 12 | I11: =VLOOKUP($D11,'Tag(Glossary)'!$B:$H,6,0)&IF(ISBLANK(VLOOKUP($D11,'Tag(Glossary)'!$B:$H,7,0)),"",CHAR(10))&VLOOKUP($D11,'Tag(Glossary)'!$B:$H,7,0) -> The unique code of an issue (a.k.a. instrument or symbol). Generally it is ISIN code but in case of Repo market it is defined as the exchange staffs want
B12: =INDEX('Interface List'!$D$7:$D$45,MATCH($C12,'Interface List'!$E$7:$E$45,0)) -> IFMDFIX0002 | C12: Security Status | D12: 336 | E12: =VLOOKUP($D12,'Tag(Glossary)'!$B:$G,2,0) -> TradingSessionID | F12: N | G12: =VLOOKUP($D12,'Tag(Glossary)'!$B:$G,4,0) -> String | H12: =VLOOKUP($D12,'Tag(Glossary)'!$B:$G,5,0) -> 2 | I12: =VLOOKUP($D12,'Tag(Glossary)'!$B:$H,6,0)&IF(ISBLANK(VLOOKUP($D12,'Tag(Glossary)'!$B:$H,7,0)),"",CHAR(10))&VLOOKUP($D12,'Tag(Glossary)'!$B:$H,7,0) -> Trading Session 01 = GT Order Load 10 = Opening Call Auction 11 = Opening Call Auction Extension 20 = Call Auction after Halt 21 = Call Auction after Halt Extension 30 = Closing Call Auction 40 = Continuous Auction 50 = VI Call Auction 51 = VI Call Auction Extension 60 = Order Accept Only 80 = Periodic Call Auction 90 = Trading Halt 99 = Board Closing
B13: =INDEX('Interface List'!$D$7:$D$45,MATCH($C13,'Interface List'!$E$7:$E$45,0)) -> IFMDFIX0002 | C13: Security Status | D13: 30651 | E13: =VLOOKUP($D13,'Tag(Glossary)'!$B:$G,2,0) -> HaltRsnCode | F13: N | G13: String | H13: 3 | I13: =VLOOKUP($D13,'Tag(Glossary)'!$B:$H,6,0)&IF(ISBLANK(VLOOKUP($D13,'Tag(Glossary)'!$B:$H,7,0)),"",CHAR(10))&VLOOKUP($D13,'Tag(Glossary)'!$B:$H,7,0) -> Halt Reason Code ▦▦ Codes ▦▦ B10 The result of the inquiry disclosure for rumor and news B11 Unsubmission of annual/half-yearly/quarterly report B21 Capital is less than 10 billion VND B23 Auditor's Opinion is adverse or disclaimer B24 Issuers default B25 Dissolution B26 Bankruptcy B27 Sanction on Business B28 Suspension by courts decision B29 False information/omission of listing document B30 Accounting standards of violation B31 Investor warning/protection B40 Issues for administration B60 Falsification of securities B70 Investor protection during a workout program B80 Bankruptcy of guarantee institution B90 Other reasons B99 When maturity date will be a holiday D11 Corresponded cash market stop trading D21 Investor warning/protection D22 Volatile price movement D23 Bankruptcy D24 Issuers default D25 Liquidation D26 Sanction on Business D27 Suspension by courts decision D28 Stock split or reverse stock split D31 HNX trading system have problem D32 Lot of HNX’s members have problem D33 VSD have problem D41 Requested by SSC O01 Volatile price movement O02 Information Disclosure Special Warning O03 Stock split or reverse stock split O04 Bond Converting O05 Capital Decrease O06 Investor warning/protection O07 Other reasons O08 Volatile price movement O09 Investor warning/protection O10 Other reasons O12 Volatile price movement (Intraday) O13 Investor warning/protection (Intraday) O14 Other reasons (Intraday) X01 Volatile price movement X02 Information Disclosure Special Warning X03 Stock split or reverse stock split X04 Bond Converting X05 Capital Decrease X06 Investor warning/protection X07 Other reasons X08 Violation on information disclosure X09 Volatile volume movement X10 Fault to fix controlled status X11 Continue to violate information disclosure when controlled X12 Volatile volume movement (Intraday) X13 Investor warning/protection (Intraday) X14 Other reasons (Intraday)
B14: =INDEX('Interface List'!$D$7:$D$45,MATCH($C14,'Interface List'!$E$7:$E$45,0)) -> IFMDFIX0002 | C14: Security Status | E14: Standard Trailer | F14: Y

Sheet Security Info Notification
B2: Security Information Notification
B4: Interface ID | C4: Interface Name | D4: Tag | E4: Field Name | F4: Req'd | G4: Format | H4: Length | I4: Comments
B5: =INDEX('Interface List'!$D$7:$D$45,MATCH($C5,'Interface List'!$E$7:$E$45,0)) -> IFMDFIX0003 | C5: Security Information Notification | E5: Standard Header | F5: Y | I5: MsgType = M7
B6: =INDEX('Interface List'!$D$7:$D$45,MATCH($C6,'Interface List'!$E$7:$E$45,0)) -> IFMDFIX0003 | C6: Security Information Notification | D6: 30001 | E6: =VLOOKUP($D6,'Tag(Glossary)'!$B:$G,2,0) -> MarketID | F6: Y | G6: =VLOOKUP($D6,'Tag(Glossary)'!$B:$G,4,0) -> String | H6: =VLOOKUP($D6,'Tag(Glossary)'!$B:$G,5,0) -> 3 | I6: =VLOOKUP($D6,'Tag(Glossary)'!$B:$H,6,0)&IF(ISBLANK(VLOOKUP($D6,'Tag(Glossary)'!$B:$H,7,0)),"",CHAR(10))&VLOOKUP($D6,'Tag(Glossary)'!$B:$H,7,0) -> ID for identifying the market <Hochiminh Exchange> - STO: HoSE Stock Market - BDO: HoSE Bond Market - RPO: HoSE Repo Market <Hanoi Exchange> - STX: HNX Listed Stock Market - BDX: HNX Government Bond Market - DVX: HNX Derivative Market - UPX: HNX UpCoM Stock Market - HCX: HNX Corporate Bond Market
B7: =INDEX('Interface List'!$D$7:$D$45,MATCH($C7,'Interface List'!$E$7:$E$45,0)) -> IFMDFIX0003 | C7: Security Information Notification | D7: 20004 | E7: =VLOOKUP($D7,'Tag(Glossary)'!$B:$G,2,0) -> BoardID | F7: Y | G7: =VLOOKUP($D7,'Tag(Glossary)'!$B:$G,4,0) -> String | H7: =VLOOKUP($D7,'Tag(Glossary)'!$B:$G,5,0) -> 2 | I7: =VLOOKUP($D7,'Tag(Glossary)'!$B:$H,6,0)&IF(ISBLANK(VLOOKUP($D7,'Tag(Glossary)'!$B:$H,7,0)),"",CHAR(10))&VLOOKUP($D7,'Tag(Glossary)'!$B:$H,7,0) -> Unique identifier to a Board where a given instrument is traded G1 : Main G2 : Pre open G3 : Post closing G4 : Odd lot G7 : Buy-in G8 : Sell-out T1 : Negotiation (regular) T4 : Negotiation (regular for Odd lot) T2 : Negotiation (pre) T3 : Negotiation (post) T6 : Negotiation (post for Odd lot) R1 : Negotiation (Repo) AL : All Boards
B8: =INDEX('Interface List'!$D$7:$D$45,MATCH($C8,'Interface List'!$E$7:$E$45,0)) -> IFMDFIX0003 | C8: Security Information Notification | D8: 55 | E8: =VLOOKUP($D8,'Tag(Glossary)'!$B:$G,2,0) -> Symbol | F8: Y | G8: =VLOOKUP($D8,'Tag(Glossary)'!$B:$G,4,0) -> String | H8: =VLOOKUP($D8,'Tag(Glossary)'!$B:$G,5,0) -> 12 | I8: =VLOOKUP($D8,'Tag(Glossary)'!$B:$H,6,0)&IF(ISBLANK(VLOOKUP($D8,'Tag(Glossary)'!$B:$H,7,0)),"",CHAR(10))&VLOOKUP($D8,'Tag(Glossary)'!$B:$H,7,0) -> The unique code of an issue (a.k.a. instrument or symbol). Generally it is ISIN code but in case of Repo market it is defined as the exchange staffs want
B9: =INDEX('Interface List'!$D$7:$D$45,MATCH($C9,'Interface List'!$E$7:$E$45,0)) -> IFMDFIX0003 | C9: Security Information Notification | D9: 20013 | E9: =VLOOKUP($D9,'Tag(Glossary)'!$B:$G,2,0) -> ReferencePrice | F9: N | G9: =VLOOKUP($D9,'Tag(Glossary)'!$B:$G,4,0) -> Price | H9: =VLOOKUP($D9,'Tag(Glossary)'!$B:$G,5,0) -> 15(9.4) | I9: =VLOOKUP($D9,'Tag(Glossary)'!$B:$H,6,0)&IF(ISBLANK(VLOOKUP($D9,'Tag(Glossary)'!$B:$H,7,0)),"",CHAR(10))&VLOOKUP($D9,'Tag(Glossary)'!$B:$H,7,0) -> Reference price of a given instrument. Price limit is determined based on this price.
B10: =INDEX('Interface List'!$D$7:$D$45,MATCH($C10,'Interface List'!$E$7:$E$45,0)) -> IFMDFIX0003 | C10: Security Information Notification | D10: 1149 | E10: =VLOOKUP($D10,'Tag(Glossary)'!$B:$G,2,0) -> HighLimitPrice | F10: N | G10: =VLOOKUP($D10,'Tag(Glossary)'!$B:$G,4,0) -> Price | H10: =VLOOKUP($D10,'Tag(Glossary)'!$B:$G,5,0) -> 15(9.4) | I10: =VLOOKUP($D10,'Tag(Glossary)'!$B:$H,6,0)&IF(ISBLANK(VLOOKUP($D10,'Tag(Glossary)'!$B:$H,7,0)),"",CHAR(10))&VLOOKUP($D10,'Tag(Glossary)'!$B:$H,7,0) -> Available high limit price for the tradig day
B11: =INDEX('Interface List'!$D$7:$D$45,MATCH($C11,'Interface List'!$E$7:$E$45,0)) -> IFMDFIX0003 | C11: Security Information Notification | D11: 1148 | E11: =VLOOKUP($D11,'Tag(Glossary)'!$B:$G,2,0) -> LowLimitPrice | F11: N | G11: =VLOOKUP($D11,'Tag(Glossary)'!$B:$G,4,0) -> Price | H11: =VLOOKUP($D11,'Tag(Glossary)'!$B:$G,5,0) -> 15(9.4) | I11: =VLOOKUP($D11,'Tag(Glossary)'!$B:$H,6,0)&IF(ISBLANK(VLOOKUP($D11,'Tag(Glossary)'!$B:$H,7,0)),"",CHAR(10))&VLOOKUP($D11,'Tag(Glossary)'!$B:$H,7,0) -> Available low limit price for the tradig day
B12: =INDEX('Interface List'!$D$7:$D$45,MATCH($C12,'Interface List'!$E$7:$E$45,0)) -> IFMDFIX0003 | C12: Security Information Notification | D12: 20014 | E12: =VLOOKUP($D12,'Tag(Glossary)'!$B:$G,2,0) -> EvaluationPrice | F12: N | G12: =VLOOKUP($D12,'Tag(Glossary)'!$B:$G,4,0) -> Price | H12: =VLOOKUP($D12,'Tag(Glossary)'!$B:$G,5,0) -> 15(9.4) | I12: =VLOOKUP($D12,'Tag(Glossary)'!$B:$H,6,0)&IF(ISBLANK(VLOOKUP($D12,'Tag(Glossary)'!$B:$H,7,0)),"",CHAR(10))&VLOOKUP($D12,'Tag(Glossary)'!$B:$H,7,0) -> Valuation price for a 'Re-Valuation' instrument. For such instrument, price limit is set based on this price until the first execution. Once the first execution is occurred, price limit is set again base on the price of the first execution.
B13: =INDEX('Interface List'!$D$7:$D$45,MATCH($C13,'Interface List'!$E$7:$E$45,0)) -> IFMDFIX0003 | C13: Security Information Notification | D13: 20015 | E13: =VLOOKUP($D13,'Tag(Glossary)'!$B:$G,2,0) -> HgstOrderPrice | F13: N | G13: =VLOOKUP($D13,'Tag(Glossary)'!$B:$G,4,0) -> Price | H13: =VLOOKUP($D13,'Tag(Glossary)'!$B:$G,5,0) -> 15 (9.4) | I13: =VLOOKUP($D13,'Tag(Glossary)'!$B:$H,6,0)&IF(ISBLANK(VLOOKUP($D13,'Tag(Glossary)'!$B:$H,7,0)),"",CHAR(10))&VLOOKUP($D13,'Tag(Glossary)'!$B:$H,7,0) -> Upper price limit for a 'Re-Valuation' instrument during the opening call auction (or until the first execution).
B14: =INDEX('Interface List'!$D$7:$D$45,MATCH($C14,'Interface List'!$E$7:$E$45,0)) -> IFMDFIX0003 | C14: Security Information Notification | D14: 20016 | E14: =VLOOKUP($D14,'Tag(Glossary)'!$B:$G,2,0) -> LwstOrderPrice | F14: N | G14: =VLOOKUP($D14,'Tag(Glossary)'!$B:$G,4,0) -> Price | H14: =VLOOKUP($D14,'Tag(Glossary)'!$B:$G,5,0) -> 15 (9.4) | I14: =VLOOKUP($D14,'Tag(Glossary)'!$B:$H,6,0)&IF(ISBLANK(VLOOKUP($D14,'Tag(Glossary)'!$B:$H,7,0)),"",CHAR(10))&VLOOKUP($D14,'Tag(Glossary)'!$B:$H,7,0) -> Lower price limit for a 'Re-Valuation' instrument during the opening call auction (or until the first execution).
B15: =INDEX('Interface List'!$D$7:$D$45,MATCH($C15,'Interface List'!$E$7:$E$45,0)) -> IFMDFIX0003 | C15: Security Information Notification | D15: 20020 | E15: =VLOOKUP($D15,'Tag(Glossary)'!$B:$G,2,0) -> ListedShares | F15: N | G15: =VLOOKUP($D15,'Tag(Glossary)'!$B:$G,4,0) -> Int | H15: =VLOOKUP($D15,'Tag(Glossary)'!$B:$G,5,0) -> 16 | I15: =VLOOKUP($D15,'Tag(Glossary)'!$B:$H,6,0)&IF(ISBLANK(VLOOKUP($D15,'Tag(Glossary)'!$B:$H,7,0)),"",CHAR(10))&VLOOKUP($D15,'Tag(Glossary)'!$B:$H,7,0) -> Number of listed stocks
B16: =INDEX('Interface List'!$D$7:$D$45,MATCH($C16,'Interface List'!$E$7:$E$45,0)) -> IFMDFIX0003 | C16: Security Information Notification | D16: 20018 | E16: =VLOOKUP($D16,'Tag(Glossary)'!$B:$G,2,0) -> ExClassType | F16: N | G16: =VLOOKUP($D16,'Tag(Glossary)'!$B:$G,4,0) -> String | H16: =VLOOKUP($D16,'Tag(Glossary)'!$B:$G,5,0) -> 2 | I16: =VLOOKUP($D16,'Tag(Glossary)'!$B:$H,6,0)&IF(ISBLANK(VLOOKUP($D16,'Tag(Glossary)'!$B:$H,7,0)),"",CHAR(10))&VLOOKUP($D16,'Tag(Glossary)'!$B:$H,7,0) -> Corporate action type that may affect reference price. 00: N/A 01: Stock Dividend/Bonus (D/B) 02: Cash Dividend 04: Right Offering (RO) 03: Stock D/B + Cash D 05: RO + Stock D/B 06: RO + Cash D 07: RO + Stock D/B + Cash D 08: Convertible Bond 16: Treasury Stock Div. P1: Stock Split P2: Stock Merge XX: Etc.
B17: =INDEX('Interface List'!$D$7:$D$45,MATCH($C17,'Interface List'!$E$7:$E$45,0)) -> IFMDFIX0003 | C17: Security Information Notification | E17: Standard Trailer | F17: Y

Sheet Symbol Closing Info
B2: Symbol Closing Information
A4: 추 | B4: Interface ID | C4: Interface Name | D4: Tag | E4: Field Name | F4: Req'd | G4: Format | H4: Length | I4: Comments
B5: =INDEX('Interface List'!$D$7:$D$45,MATCH($C5,'Interface List'!$E$7:$E$45,0)) -> IFMDFIX0004 | C5: Symbol Closing Information | E5: Standard Header | F5: Y | I5: MsgType = M8
B6: =INDEX('Interface List'!$D$7:$D$45,MATCH($C6,'Interface List'!$E$7:$E$45,0)) -> IFMDFIX0004 | C6: Symbol Closing Information | D6: 30001 | E6: =VLOOKUP($D6,'Tag(Glossary)'!$B:$G,2,0) -> MarketID | F6: Y | G6: =VLOOKUP($D6,'Tag(Glossary)'!$B:$G,4,0) -> String | H6: =VLOOKUP($D6,'Tag(Glossary)'!$B:$G,5,0) -> 3 | I6: =VLOOKUP($D6,'Tag(Glossary)'!$B:$H,6,0)&IF(ISBLANK(VLOOKUP($D6,'Tag(Glossary)'!$B:$H,7,0)),"",CHAR(10))&VLOOKUP($D6,'Tag(Glossary)'!$B:$H,7,0) -> ID for identifying the market <Hochiminh Exchange> - STO: HoSE Stock Market - BDO: HoSE Bond Market - RPO: HoSE Repo Market <Hanoi Exchange> - STX: HNX Listed Stock Market - BDX: HNX Government Bond Market - DVX: HNX Derivative Market - UPX: HNX UpCoM Stock Market - HCX: HNX Corporate Bond Market
B7: =INDEX('Interface List'!$D$7:$D$45,MATCH($C7,'Interface List'!$E$7:$E$45,0)) -> IFMDFIX0004 | C7: Symbol Closing Information | D7: 20004 | E7: =VLOOKUP($D7,'Tag(Glossary)'!$B:$G,2,0) -> BoardID | F7: Y | G7: =VLOOKUP($D7,'Tag(Glossary)'!$B:$G,4,0) -> String | H7: =VLOOKUP($D7,'Tag(Glossary)'!$B:$G,5,0) -> 2 | I7: =VLOOKUP($D7,'Tag(Glossary)'!$B:$H,6,0)&IF(ISBLANK(VLOOKUP($D7,'Tag(Glossary)'!$B:$H,7,0)),"",CHAR(10))&VLOOKUP($D7,'Tag(Glossary)'!$B:$H,7,0) -> Unique identifier to a Board where a given instrument is traded G1 : Main G2 : Pre open G3 : Post closing G4 : Odd lot G7 : Buy-in G8 : Sell-out T1 : Negotiation (regular) T4 : Negotiation (regular for Odd lot) T2 : Negotiation (pre) T3 : Negotiation (post) T6 : Negotiation (post for Odd lot) R1 : Negotiation (Repo) AL : All Boards
B8: =INDEX('Interface List'!$D$7:$D$45,MATCH($C8,'Interface List'!$E$7:$E$45,0)) -> IFMDFIX0004 | C8: Symbol Closing Information | D8: 55 | E8: =VLOOKUP($D8,'Tag(Glossary)'!$B:$G,2,0) -> Symbol | F8: Y | G8: =VLOOKUP($D8,'Tag(Glossary)'!$B:$G,4,0) -> String | H8: =VLOOKUP($D8,'Tag(Glossary)'!$B:$G,5,0) -> 12 | I8: =VLOOKUP($D8,'Tag(Glossary)'!$B:$H,6,0)&IF(ISBLANK(VLOOKUP($D8,'Tag(Glossary)'!$B:$H,7,0)),"",CHAR(10))&VLOOKUP($D8,'Tag(Glossary)'!$B:$H,7,0) -> The unique code of an issue (a.k.a. instrument or symbol). Generally it is ISIN code but in case of Repo market it is defined as the exchange staffs want
B9: =INDEX('Interface List'!$D$7:$D$45,MATCH($C9,'Interface List'!$E$7:$E$45,0)) -> IFMDFIX0004 | C9: Symbol Closing Information | D9: 20026 | E9: =VLOOKUP($D9,'Tag(Glossary)'!$B:$G,2,0) -> SymbolCloseInfoPx | F9: Y | G9: =VLOOKUP($D9,'Tag(Glossary)'!$B:$G,4,0) -> Price | H9: =VLOOKUP($D9,'Tag(Glossary)'!$B:$G,5,0) -> 15(9.4) | I9: =VLOOKUP($D9,'Tag(Glossary)'!$B:$H,6,0)&IF(ISBLANK(VLOOKUP($D9,'Tag(Glossary)'!$B:$H,7,0)),"",CHAR(10))&VLOOKUP($D9,'Tag(Glossary)'!$B:$H,7,0) -> The last execution price of that day. If there is no execution it is replaced with the reference price, and if no reference price is given then it will be 0 (zero)
B10: =INDEX('Interface List'!$D$7:$D$45,MATCH($C10,'Interface List'!$E$7:$E$45,0)) -> IFMDFIX0004 | C10: Symbol Closing Information | D10: 30541 | E10: =VLOOKUP($D10,'Tag(Glossary)'!$B:$G,2,0) -> SymbolCloseInfoYield | F10: Y | G10: =VLOOKUP($D10,'Tag(Glossary)'!$B:$G,4,0) -> Float | H10: =VLOOKUP($D10,'Tag(Glossary)'!$B:$G,5,0) -> 13(5.6) | I10: =VLOOKUP($D10,'Tag(Glossary)'!$B:$H,6,0)&IF(ISBLANK(VLOOKUP($D10,'Tag(Glossary)'!$B:$H,7,0)),"",CHAR(10))&VLOOKUP($D10,'Tag(Glossary)'!$B:$H,7,0) -> Final yield of a bond calculated using the closing price of that day
B11: =INDEX('Interface List'!$D$7:$D$45,MATCH($C11,'Interface List'!$E$7:$E$45,0)) -> IFMDFIX0004 | C11: Symbol Closing Information | D11: 20027 | E11: =VLOOKUP($D11,'Tag(Glossary)'!$B:$G,2,0) -> SymbolCloseInfoPxType | F11: Y | G11: =VLOOKUP($D11,'Tag(Glossary)'!$B:$G,4,0) -> String | H11: =VLOOKUP($D11,'Tag(Glossary)'!$B:$G,5,0) -> 1 | I11: =VLOOKUP($D11,'Tag(Glossary)'!$B:$H,6,0)&IF(ISBLANK(VLOOKUP($D11,'Tag(Glossary)'!$B:$H,7,0)),"",CHAR(10))&VLOOKUP($D11,'Tag(Glossary)'!$B:$H,7,0) -> Type of closing price 1: Actual Trade 2: Biased Quotation 3: No Trade 4: Biased Quotation of an Re-Valuation Instr.
B12: =INDEX('Interface List'!$D$7:$D$45,MATCH($C12,'Interface List'!$E$7:$E$45,0)) -> IFMDFIX0004 | C12: Symbol Closing Information | E12: Standard Trailer | F12: Y

Sheet Volatility Interruption
B2: Volatility Interruption
B4: Interface ID | C4: Interface Name | D4: Tag | E4: Field Name | F4: Req'd | G4: Format | H4: Length | I4: Comments
B5: =INDEX('Interface List'!$D$7:$D$45,MATCH($C5,'Interface List'!$E$7:$E$45,0)) -> IFMDFIX0005 | C5: Volatility Interruption | E5: Standard Header | F5: Y | I5: MsgType = MD
B6: =INDEX('Interface List'!$D$7:$D$45,MATCH($C6,'Interface List'!$E$7:$E$45,0)) -> IFMDFIX0005 | C6: Volatility Interruption | D6: 30001 | E6: =VLOOKUP($D6,'Tag(Glossary)'!$B:$G,2,0) -> MarketID | F6: Y | G6: =VLOOKUP($D6,'Tag(Glossary)'!$B:$G,4,0) -> String | H6: =VLOOKUP($D6,'Tag(Glossary)'!$B:$G,5,0) -> 3 | I6: =VLOOKUP($D6,'Tag(Glossary)'!$B:$H,6,0)&IF(ISBLANK(VLOOKUP($D6,'Tag(Glossary)'!$B:$H,7,0)),"",CHAR(10))&VLOOKUP($D6,'Tag(Glossary)'!$B:$H,7,0) -> ID for identifying the market <Hochiminh Exchange> - STO: HoSE Stock Market - BDO: HoSE Bond Market - RPO: HoSE Repo Market <Hanoi Exchange> - STX: HNX Listed Stock Market - BDX: HNX Government Bond Market - DVX: HNX Derivative Market - UPX: HNX UpCoM Stock Market - HCX: HNX Corporate Bond Market
B7: =INDEX('Interface List'!$D$7:$D$45,MATCH($C7,'Interface List'!$E$7:$E$45,0)) -> IFMDFIX0005 | C7: Volatility Interruption | D7: 20004 | E7: =VLOOKUP($D7,'Tag(Glossary)'!$B:$G,2,0) -> BoardID | F7: Y | G7: =VLOOKUP($D7,'Tag(Glossary)'!$B:$G,4,0) -> String | H7: =VLOOKUP($D7,'Tag(Glossary)'!$B:$G,5,0) -> 2 | I7: =VLOOKUP($D7,'Tag(Glossary)'!$B:$H,6,0)&IF(ISBLANK(VLOOKUP($D7,'Tag(Glossary)'!$B:$H,7,0)),"",CHAR(10))&VLOOKUP($D7,'Tag(Glossary)'!$B:$H,7,0) -> Unique identifier to a Board where a given instrument is traded G1 : Main G2 : Pre open G3 : Post closing G4 : Odd lot G7 : Buy-in G8 : Sell-out T1 : Negotiation (regular) T4 : Negotiation (regular for Odd lot) T2 : Negotiation (pre) T3 : Negotiation (post) T6 : Negotiation (post for Odd lot) R1 : Negotiation (Repo) AL : All Boards
B8: =INDEX('Interface List'!$D$7:$D$45,MATCH($C8,'Interface List'!$E$7:$E$45,0)) -> IFMDFIX0005 | C8: Volatility Interruption | D8: 55 | E8: =VLOOKUP($D8,'Tag(Glossary)'!$B:$G,2,0) -> Symbol | F8: Y | G8: =VLOOKUP($D8,'Tag(Glossary)'!$B:$G,4,0) -> String | H8: =VLOOKUP($D8,'Tag(Glossary)'!$B:$G,5,0) -> 12 | I8: =VLOOKUP($D8,'Tag(Glossary)'!$B:$H,6,0)&IF(ISBLANK(VLOOKUP($D8,'Tag(Glossary)'!$B:$H,7,0)),"",CHAR(10))&VLOOKUP($D8,'Tag(Glossary)'!$B:$H,7,0) -> The unique code of an issue (a.k.a. instrument or symbol). Generally it is ISIN code but in case of Repo market it is defined as the exchange staffs want
B9: =INDEX('Interface List'!$D$7:$D$45,MATCH($C9,'Interface List'!$E$7:$E$45,0)) -> IFMDFIX0005 | C9: Volatility Interruption | D9: 20030 | E9: =VLOOKUP($D9,'Tag(Glossary)'!$B:$G,2,0) -> VITypeCode | F9: Y | G9: =VLOOKUP($D9,'Tag(Glossary)'!$B:$G,4,0) -> String | H9: =VLOOKUP($D9,'Tag(Glossary)'!$B:$G,5,0) -> 1 | I9: =VLOOKUP($D9,'Tag(Glossary)'!$B:$H,6,0)&IF(ISBLANK(VLOOKUP($D9,'Tag(Glossary)'!$B:$H,7,0)),"",CHAR(10))&VLOOKUP($D9,'Tag(Glossary)'!$B:$H,7,0) -> Indicates whether VI is activated or released. 1 = Activated 2 = Released
B10: =INDEX('Interface List'!$D$7:$D$45,MATCH($C10,'Interface List'!$E$7:$E$45,0)) -> IFMDFIX0005 | C10: Volatility Interruption | D10: 20031 | E10: =VLOOKUP($D10,'Tag(Glossary)'!$B:$G,2,0) -> VIKindCode | F10: Y | G10: =VLOOKUP($D10,'Tag(Glossary)'!$B:$G,4,0) -> String | H10: =VLOOKUP($D10,'Tag(Glossary)'!$B:$G,5,0) -> 1 | I10: =VLOOKUP($D10,'Tag(Glossary)'!$B:$H,6,0)&IF(ISBLANK(VLOOKUP($D10,'Tag(Glossary)'!$B:$H,7,0)),"",CHAR(10))&VLOOKUP($D10,'Tag(Glossary)'!$B:$H,7,0) -> Indicates which kind of VI is activated or released. 1 = Static VI 2 = Dynamic VI 3 = Static VI + Dynamic VI
B11: =INDEX('Interface List'!$D$7:$D$45,MATCH($C11,'Interface List'!$E$7:$E$45,0)) -> IFMDFIX0005 | C11: Volatility Interruption | D11: 20032 | E11: =VLOOKUP($D11,'Tag(Glossary)'!$B:$G,2,0) -> StaticVIBasePrice | F11: Y | G11: =VLOOKUP($D11,'Tag(Glossary)'!$B:$G,4,0) -> Price | H11: =VLOOKUP($D11,'Tag(Glossary)'!$B:$G,5,0) -> 15 (9.4) | I11: =VLOOKUP($D11,'Tag(Glossary)'!$B:$H,6,0)&IF(ISBLANK(VLOOKUP($D11,'Tag(Glossary)'!$B:$H,7,0)),"",CHAR(10))&VLOOKUP($D11,'Tag(Glossary)'!$B:$H,7,0) -> Indicates static VI reference price. Price range for static VI is determined based on this price, and static VI is activated when an order is about to be executed outside the VI price range.
B12: =INDEX('Interface List'!$D$7:$D$45,MATCH($C12,'Interface List'!$E$7:$E$45,0)) -> IFMDFIX0005 | C12: Volatility Interruption | D12: 20047 | E12: =VLOOKUP($D12,'Tag(Glossary)'!$B:$G,2,0) -> DynamicVIBasePrice | F12: Y | G12: =VLOOKUP($D12,'Tag(Glossary)'!$B:$G,4,0) -> Price | H12: =VLOOKUP($D12,'Tag(Glossary)'!$B:$G,5,0) -> 15 (9.4) | I12: =VLOOKUP($D12,'Tag(Glossary)'!$B:$H,6,0)&IF(ISBLANK(VLOOKUP($D12,'Tag(Glossary)'!$B:$H,7,0)),"",CHAR(10))&VLOOKUP($D12,'Tag(Glossary)'!$B:$H,7,0) -> Indicates dynamic VI reference price. Price range for dynamic VI is determined based on this price, and dynamic VI is activated when an order is about to be executed outside the VI price range.
B13: =INDEX('Interface List'!$D$7:$D$45,MATCH($C13,'Interface List'!$E$7:$E$45,0)) -> IFMDFIX0005 | C13: Volatility Interruption | D13: 20033 | E13: =VLOOKUP($D13,'Tag(Glossary)'!$B:$G,2,0) -> VIPrice | F13: Y | G13: =VLOOKUP($D13,'Tag(Glossary)'!$B:$G,4,0) -> Price | H13: =VLOOKUP($D13,'Tag(Glossary)'!$B:$G,5,0) -> 15 (9.4) | I13: =VLOOKUP($D13,'Tag(Glossary)'!$B:$H,6,0)&IF(ISBLANK(VLOOKUP($D13,'Tag(Glossary)'!$B:$H,7,0)),"",CHAR(10))&VLOOKUP($D13,'Tag(Glossary)'!$B:$H,7,0) -> VI Triggering Price
